<?xml version="1.0"?>

<robot xmlns:xacro="http://www.ros.org/wiki/xacro" name="robo">
    <xacro:include filename="$(find robo_description)/URDF/material.xacro" />
    <xacro:include filename="$(find robo_description)/URDF/robot.gazebo" />

    <!-- Gazebo refrence materials-->

  <gazebo reference="base">
    <material>Gazebo/Yellow</material>
  </gazebo>

  <gazebo reference="right_front_wheel">
   <material>Gazebo/Black</material>
  </gazebo>

  <gazebo reference="right_back_wheel">
   <material>Gazebo/Black</material>
  </gazebo>

  <gazebo reference="left_front_wheel">
   <material>Gazebo/Black</material>
  </gazebo>

  <gazebo reference="left_back_wheel">
   <material>Gazebo/Black</material>
  </gazebo>

  <gazebo reference="camera_link">
    <material>Gazebo/Red</material>
  </gazebo>  


    <!-- base -->
<link name="dummy"></link>

<link name="base">
    <inertial>
            <mass value="5.0"/>
            <origin xyz="0.0 0 0.1" rpy=" 0 0 0"/>
            <inertia
          ixx="0.1" ixy="0" ixz="0"
          iyy="0.1" iyz="0"
          izz="0.1"
            />
    </inertial>
    <visual name="base_visual">
        <origin xyz="0.0 0.0 0.0" rpy="0.0 0.0 0.0"/>
        <geometry>
            <box size="0.3 0.4 0.1"/>
        </geometry>
        <material name="yellow"> </material>
    </visual>
    <collision>
        <origin xyz="0.0 0.0 0.0" rpy="0.0 0.0 0.0"/>
        <geometry>
            <box size="0.3 0.4 0.1"/>
        </geometry>
    </collision>
</link>
<joint name="dummy_joint" type="fixed">
     <parent link="dummy"/>
     <child link="base"/>
   </joint>

<link name="holder">
  <inertial>
    <origin xyz="0.0 0.0 0.0" rpy="0.0 0.0 0.0"/>
    <mass value="0.5"/>
    <inertia ixx="0.0" ixy="0.0" ixz="0.0" iyy="0.0" iyz="0.0" izz="0.0"/>
  </inertial>
  <visual name="holder_visual">
    <origin xyz="0.0 0.0 0.0" rpy="0.0 0.0 0.0"/>
    <geometry>
      <box size="0.1 0.1 0.05"/>
    </geometry>
    <material name="green">
    </material>
  </visual>
  <collision>
    <origin xyz="0.0 0.0 0.0" rpy="0.0 0.0 0.0"/>
    <geometry>
      <box size="0.1 0.1 0.05"/>
    </geometry>
  </collision>
</link>

<joint name="holder_joint" type="fixed">
  <origin xyz="0.0 0.0 0.075" rpy="0.0 0.0 0.0"/>
  <parent link="base"/>
  <child link="holder"/>
  <axis xyz="0.0 0.0 0.0"/>
  <limit lower="0.0" upper="0.0" effort="0.0" velocity="0.0"/>
</joint>

<!-- right_front_wheel-->

<link name="right_front_wheel">
    <inertial>
            <mass value="0.2"/>
            <origin rpy="0 1.5707 1.5707" xyz="0 0 0"/>
            <inertia ixx="0.00052666666" ixy="0" ixz="0" iyy="0.00052666666" iyz="0" izz="0.001"/>
    </inertial>
    <visual name="r_f_wheel_visual">
        <origin xyz="0.0 0.0 0.0" rpy="0.0 0.0 0.0"/>
        <geometry>
        
            <cylinder radius="0.1" length="0.1"/>
            
        </geometry>
        <material name="black"></material>
    </visual>
    <collision>
        <origin xyz="0.0 0.0 0.0" rpy="0.0 0.0 0.0"/>
        <geometry>
            <cylinder radius="0.1" length="0.1"/>
        </geometry>
    </collision>
</link>
<joint name="r_f_wheel" type="continuous">
    <origin xyz="0.2 0.15 0.0" rpy="0.0 1.577 0.0"/>
    <parent link="base"/>
    <child link="right_front_wheel"/>
    <axis xyz="0.0 0.0 -1"/>
    <limit lower="0.0" upper="0.0" effort="0.0" velocity="0.0"/>
</joint>

<!-- right_back_wheel-->
<link name="right_back_wheel">
    <inertial>
            <mass value="0.2"/>
            <origin rpy="0 1.5707 1.5707" xyz="0 0 0"/>
            <inertia ixx="0.00052666666" ixy="0" ixz="0" iyy="0.00052666666" iyz="0" izz="0.001"/>
    </inertial>
    <visual name="r_b_wheel_visual">
        <origin xyz="0.0 0.0 0.0" rpy="0.0 0.0 0.0"/>
        <geometry>
        
            <cylinder radius="0.1" length="0.1"/>
            
        </geometry>
        <material name="black"></material>
    </visual>
    <collision>
        <origin xyz="0.0 0.0 0.0" rpy="0.0 0.0 0.0"/>
        <geometry>
            <cylinder radius="0.1" length="0.1"/>
        </geometry>
    </collision>
</link>
<joint name="r_b_wheel" type="continuous">
    <origin xyz="0.2 -0.15 0.0" rpy="0.0 1.577 0.0"/>
    <parent link="base"/>
    <child link="right_back_wheel"/>
    <axis xyz="0.0 0.0 -1"/>
    <limit lower="0.0" upper="0.0" effort="0.0" velocity="0.0"/>
</joint>

<!--left_front_wheel -->
<link name="left_front_wheel">
    <inertial>
            <mass value="0.2"/>
            <origin rpy="0 1.5707 1.5707" xyz="0 0 0"/>
            <inertia ixx="0.00052666666" ixy="0" ixz="0" iyy="0.00052666666" iyz="0" izz="0.001"/>
    </inertial>
    <visual name="l_f_wheel_visual">
        <origin xyz="0.0 0.0 0.0" rpy="0.0 0.0 0.0"/>
        <geometry>
        
            <cylinder radius="0.1" length="0.1"/>
            
        </geometry>
        <material name="black"></material>
    </visual>
    <collision>
        <origin xyz="0.0 0.0 0.0" rpy="0.0 0.0 0.0"/>
        <geometry>
            <cylinder radius="0.1" length="0.1"/>
        </geometry>
    </collision>
</link>
<joint name="l_f_wheel" type="continuous">
    <origin xyz="-0.2 0.15 0.0" rpy="0.0 1.577 0.0"/>
    <parent link="base"/>
    <child link="left_front_wheel"/>
    <axis xyz="0.0 0.0 -1"/>
    <limit lower="0.0" upper="0.0" effort="0.0" velocity="0.0"/>
</joint>

<!--left_back_wheel -->
<link name="left_back_wheel">
    <inertial>
            <mass value="0.2"/>
            <origin rpy="0 1.5707 1.5707" xyz="0 0 0"/>
            <inertia ixx="0.00052666666" ixy="0" ixz="0" iyy="0.00052666666" iyz="0" izz="0.001"/>
    </inertial>
    <visual name="l_f_wheel_visual">
        <origin xyz="0.0 0.0 0.0" rpy="0.0 0.0 0.0"/>
        <geometry>
        
            <cylinder radius="0.1" length="0.1"/>
            
        </geometry>
        <material name="black"></material>
    </visual>
    <collision>
        <origin xyz="0.0 0.0 0.0" rpy="0.0 0.0 0.0"/>
        <geometry>
            <cylinder radius="0.1" length="0.1"/>
        </geometry>
    </collision>
</link>
<joint name="l_b_wheel" type="continuous">
    <origin xyz="-0.2 -0.15 0.0" rpy="0.0 1.577 0.0"/>
    <parent link="base"/>
    <child link="left_back_wheel"/>
    <axis xyz="0.0 0.0 -1"/>
    <limit lower="0.0" upper="0.0" effort="0.0" velocity="0.0"/>
</joint>
<!-- camera-->
  <joint name="camera_joint" type="fixed">
    <axis xyz="0 1 0" />
    <origin xyz="0 0.225 0" rpy="0 0 1.577"/>
    <parent link="base"/>
    <child link="camera_link"/>
  </joint>

  <link name="camera_link">
    <collision>
      <origin xyz="0 0 0" rpy="0 0 0"/>
      <geometry>
    <box size="0.05 0.05 0.1"/>
      </geometry>
    </collision>

    <visual>
      <origin xyz="0 0 0" rpy="0 0 0"/>
      <geometry>
    <box size="0.05 0.1 0.05 "/>
      </geometry>
      <material name="red"/>
    </visual>

    <inertial>
      <mass value="1e-5" />
      <origin xyz="0 0 0" rpy="0 0 0"/>
      <inertia ixx="1e-6" ixy="0" ixz="0" iyy="1e-6" iyz="0" izz="1e-6" />
    </inertial>
  </link>

  

  <!-- Hokuyo Laser -->
  <link name="hokuyo_link">
    <collision>
      <origin xyz="0 0 0" rpy="0 0 0"/>
      <geometry>
    <box size="0.1 0.1 0.1"/>
      </geometry>
    </collision>

    <visual>
      <origin xyz="0 0 0" rpy="0 0 0"/>
      <geometry>
        <mesh filename="package://robo_description/meshes/hokuyo.dae"/>
      </geometry>
    </visual>

    <inertial>
      <mass value="1e-5" />
      <origin xyz="0 0 0" rpy="0 0 0"/>
      <inertia ixx="1e-6" ixy="0" ixz="0" iyy="1e-6" iyz="0" izz="1e-6" />
    </inertial>
  </link>

  <joint name="hokuyo_joint" type="fixed">
    <axis xyz="0 1 0" />
    <origin xyz="0 0 0.1355" rpy="0 0 1.577"/>
    <parent link="base"/>
    <child link="hokuyo_link"/>
  </joint>

</robot>