<?xml version="1.0"?>

<robot xmlns:xacro="http://www.ros.org/wiki/xacro" name="robot">
    <!--xacro:include filename="/home/el-shamy/Desktop/task/robo/src/robo_description/URDF/material.xacro"/-->
   
 
    <link name="base">
        <visual name="base_visual">
            <origin xyz="0.0 0.0 0.0" rpy="0.0 0.0 0.0"/>
            <geometry>
                <box size="0.2 0.3 0.1"/>
            </geometry>
            <material name="PLA_yellow">
                <color rgba="1.0 0.0 0.0 1.0"/>
                <texture filename=""/>
            </material>
        </visual>
        <collision>
            <origin xyz="0.0 0.0 0.0" rpy="0.0 0.0 0.0"/>
            <geometry>
                <box size="0.2 0.3 0.1"/>
            </geometry>
        </collision>
    </link>
    <link name="wheel_L">
        
        <visual name="wheel_L_visual">
            <origin xyz="0.0 0.0 0.0" rpy="0.0 0.0 0.0"/>
            <geometry>
                <cylinder radius="0.1" length="0.05"/>
            </geometry>
            <material name="rubber">
                <color rgba="1.0 0.0 0.0 1.0"/>
                <texture filename=""/>
            </material>
        </visual>
        <collision>
            <origin xyz="0.0 0.0 0.0" rpy="0.0 0.0 0.0"/>
            <geometry>
                <cylinder radius="0.1" length="0.05"/>
            </geometry>
        </collision>
    </link>
    <link name="wheel_R">
        
        <visual name="wheel_R_visual">
            <origin xyz="0.0 0.0 0.0" rpy="0.0 0.0 0.0"/>
            <geometry>
                <cylinder radius="0.1" length="0.05"/>
            </geometry>
            <material name="rubber">
                <color rgba="1.0 0.0 0.0 1.0"/>
                <texture filename=""/>
            </material>
        </visual>
        <collision>
            <origin xyz="0.0 0.0 0.0" rpy="0.0 0.0 0.0"/>
            <geometry>
                <cylinder radius="0.1" length="0.05"/>
            </geometry>
        </collision>
    </link>
    <link name="holder">
        
        <visual name="holder_visual">
            <origin xyz="0.0 0.0 0.00" rpy="0.0 0.0 0.0"/>
            <geometry>
                <box size="0.06 0.06 0.03"/>
            </geometry>
            <material name="PLA">
                <color rgba="1.0 0.0 0.0 1.0"/>
                <texture filename=""/>
            </material>
        </visual>
        <collision>
            <origin xyz="0.0 0.0 0.00" rpy="0.0 0.0 0.0"/>
            <geometry>
                <box size="0.06 0.06 0.03"/>
            </geometry>
        </collision>
    </link>
    <link name="caster_wheel">
        
        <visual name="caster_wheel_visual">
            <origin xyz="0.0 0.0 0.0" rpy="0.0 0.0 0.0"/>
            <geometry>
                <sphere radius="0.03"/>
            </geometry>
            <material name="metal">
                <color rgba="1.0 0.0 0.0 1.0"/>
                <texture filename=""/>
            </material>
        </visual>
        <collision>
            <origin xyz="0.0 0.0 0.0" rpy="0.0 0.0 0.0"/>
            <geometry>
                <sphere radius="0.03"/>
            </geometry>
        </collision>
    </link>

    <link name="camera">
        
        <visual name="camera_visual">
            <origin xyz="0.0 0.0 0.0" rpy="0.0 0.0 0.0"/>
            <geometry>
                <box size="0.075 0.05 0.05"/>
            </geometry>
            <material name="PLA_blue">
                <color rgba="1.0 0.0 0.0 1.0"/>
                <texture filename=""/>
            </material>
        </visual>
        <collision>
            <origin xyz="0.0 0.0 0.0" rpy="0.0 0.0 0.0"/>
            <geometry>
                <box size="0.0 0.0 0.0"/>
            </geometry>
        </collision>
    </link>
    <link name="lidar">
        
        <visual name="lidar_visual">
            <origin xyz="0.0 0.0 0.0" rpy="0.0 0.0 0.0"/>
            <geometry>
                <cylinder radius="0.05" length="0.05"/>
            </geometry>
            <material name="PLA_orange">
            </material>
        </visual>
        <collision>
            <origin xyz="0.0 0.0 1.0" rpy="0.0 0.0 0.0"/>
            <geometry>
                <cylinder radius="0.05" length="0.05"/>                
            </geometry>
        </collision>
    </link>

    <link name="lidar_base">
        <visual name="lidar_base_visual">
            <origin xyz="0.0 0.0 0.0" rpy="0.0 0.0 0.0"/>
            <geometry>
                <box size="0.1 0.125 0.03"/>
            </geometry>
            <material name="PLA_orange">
            </material>
        </visual>
        <collision>
            <origin xyz="0.0 0.0 0.0" rpy="0.0 0.0 0.0"/>
            <geometry>
                <box size="0.1 0.125 0.03"/>
            </geometry>
        </collision>
    </link>
    <joint name="lidar" type="fixed">
        <origin xyz="0.0 0.01 0.02" rpy="0.0 0.0 0.0"/>
        <parent link="lidar_base"/>
        <child link="lidar"/>
        <axis xyz="0.0 0.0 0.0"/>
        <limit lower="0.0" upper="0.0" effort="0.0" velocity="0.0"/>
    </joint>

    <joint name="lidar_base" type="fixed">
        <origin xyz="0.0 0.0 0.065" rpy="0.0 0.0 0.0"/>
        <parent link="base"/>
        <child link="lidar_base"/>
        <axis xyz="0.0 0.0 0.0"/>
        <limit lower="0.0" upper="0.0" effort="0.0" velocity="0.0"/>
    </joint>

    <joint name="camera" type="fixed">
        <origin xyz="0.0 -0.175 0.0" rpy="0.0 0.0 0.0"/>
        <parent link="base"/>
        <child link="camera"/>
        <axis xyz="0.0 0.0 0.0"/>
        <limit lower="0.0" upper="0.0" effort="0.0" velocity="0.0"/>
    </joint>

    <joint name="L_wheel" type="revolute">
        <origin xyz="0.125 0.075 0.0" rpy="0.0 1.57 0.0"/>
        <parent link="base"/>
        <child link="wheel_L"/>
        <axis xyz="1 0.0 0.0"/>
        <limit lower="0.0" upper="0.0" effort="0.0" velocity="0.0"/>
    </joint>
    <joint name="R_wheel" type="revolute">
        <origin xyz="-0.125 0.075 0.0" rpy="0.0 1.57 0.0"/>
        <parent link="base"/>
        <child link="wheel_R"/>
        <axis xyz="1 0.0 0.0"/>
        <limit lower="0.0" upper="0.0" effort="0.0" velocity="0.0"/>
    </joint>
    <joint name="caster_holder" type="fixed">
        <origin xyz="0.0 -0.1 -0.065" rpy="0.0 0.0 0.0"/>
        <parent link="base"/>
        <child link="holder"/>
        <axis xyz="0.0 0.0 0.0"/>
        <limit lower="0.0" upper="0.0" effort="0.0" velocity="0.0"/>
    </joint>
    <joint name="caster_wheel" type="continuous">
        <origin xyz="0.0 0.0 -0.0075" rpy="0.0 0.0 0.0"/>
        <parent link="holder"/>
        <child link="caster_wheel"/>
        <axis xyz="0.0 0.0 0.0"/>
        <limit lower="0.0" upper="0.0" effort="0.0" velocity="0.0"/>
    </joint>
    
</robot>